<?xml version="1.0" encoding="utf-8"?>
<!-- This URDF was automatically created by SolidWorks to URDF Exporter! Originally created by Stephen Brawner (brawner@gmail.com) 
     Commit Version: 1.5.1-0-g916b5db  Build Version: 1.5.7152.31018
     For more information, please see http://wiki.ros.org/sw_urdf_exporter -->
<robot
  name="4wheel_sus">
  <link
    name="base_link">
    <inertial>
      <origin
        xyz="-0.101222450007234 -0.134712291964518 0.0611878805385779"
        rpy="0 0 0" />
      <mass
        value="5.04599768700975" />
      <inertia
        ixx="0.0199585188421209"
        ixy="8.49633695552677E-07"
        ixz="3.57924483955382E-07"
        iyy="0.0133780567917248"
        iyz="-8.69413175240183E-06"
        izz="0.0204011323429147" />
    </inertial>
    <visual>
      <origin
        xyz="0 0 0"
        rpy="0 0 0" />
      <geometry>
        <mesh
          filename="package://4wheel_sus/meshes/base_link.STL" />
      </geometry>
      <material
        name="">
        <color
          rgba="0.752941176470588 0.752941176470588 0.752941176470588 1" />
      </material>
    </visual>
    <collision>
      <origin
        xyz="0 0 0"
        rpy="0 0 0" />
      <geometry>
        <mesh
          filename="package://4wheel_sus/meshes/base_link.STL" />
      </geometry>
    </collision>
  </link>
  <link
    name="RFS">
    <inertial>
      <origin
        xyz="0.0724473276378504 -0.031683252131476 0.0253402400459296"
        rpy="0 0 0" />
      <mass
        value="0.26437001106024" />
      <inertia
        ixx="3.20746276473134E-05"
        ixy="1.44118283521256E-07"
        ixz="6.30853084344777E-08"
        iyy="6.22704126338856E-05"
        iyz="-2.01894652764195E-07"
        izz="6.28519936954001E-05" />
    </inertial>
    <visual>
      <origin
        xyz="0 0 0"
        rpy="0 0 0" />
      <geometry>
        <mesh
          filename="package://4wheel_sus/meshes/RFS.STL" />
      </geometry>
      <material
        name="">
        <color
          rgba="0.752941176470588 0.752941176470588 0.752941176470588 1" />
      </material>
    </visual>
    <collision>
      <origin
        xyz="0 0 0"
        rpy="0 0 0" />
      <geometry>
        <mesh
          filename="package://4wheel_sus/meshes/RFS.STL" />
      </geometry>
    </collision>
  </link>
  <joint
    name="RFS"
    type="prismatic">
    <origin
      xyz="0.10792 -0.012126 0.032608"
      rpy="2.834 0 -3.1416" />
    <parent
      link="base_link" />
    <child
      link="RFS" />
    <axis
      xyz="0 0.3028 -0.95305" />
    <limit
      lower="0"
      upper="0"
      effort="0"
      velocity="0" />
  </joint>
  <link
    name="RFW">
    <inertial>
      <origin
        xyz="0.0176842754269317 0.00317905396079527 -0.000103745604902616"
        rpy="0 0 0" />
      <mass
        value="0.193585420779862" />
      <inertia
        ixx="0.000253081141332253"
        ixy="-7.98059977897539E-24"
        ixz="4.95236102613101E-21"
        iyy="0.000136818598566517"
        iyz="4.2351647362715E-22"
        izz="0.000136818598566517" />
    </inertial>
    <visual>
      <origin
        xyz="0 0 0"
        rpy="0 0 0" />
      <geometry>
        <mesh
          filename="package://4wheel_sus/meshes/RFW.STL" />
      </geometry>
      <material
        name="">
        <color
          rgba="1 1 1 1" />
      </material>
    </visual>
    <collision>
      <origin
        xyz="0 0 0"
        rpy="0 0 0" />
      <geometry>
        <mesh
          filename="package://4wheel_sus/meshes/RFW.STL" />
      </geometry>
    </collision>
  </link>
  <joint
    name="RFW"
    type="continuous">
    <origin
      xyz="0.036171 -0.029249 0.061437"
      rpy="-1.8458 0 -3.1416" />
    <parent
      link="RFS" />
    <child
      link="RFW" />
    <axis
      xyz="1 0 0" />
    <limit
      effort="3.1"
      velocity="7" />
  </joint>
  <link
    name="LFS">
    <inertial>
      <origin
        xyz="0.0666875210853821 -0.0256174029954349 0.0272583251967583"
        rpy="0 0 0" />
      <mass
        value="0.26437001106024" />
      <inertia
        ixx="3.20746276473134E-05"
        ixy="-1.44118283521521E-07"
        ixz="-6.30853084343059E-08"
        iyy="6.22704126338856E-05"
        iyz="-2.018946527642E-07"
        izz="6.28519936954001E-05" />
    </inertial>
    <visual>
      <origin
        xyz="0 0 0"
        rpy="0 0 0" />
      <geometry>
        <mesh
          filename="package://4wheel_sus/meshes/LFS.STL" />
      </geometry>
      <material
        name="">
        <color
          rgba="0.752941176470588 0.752941176470588 0.752941176470588 1" />
      </material>
    </visual>
    <collision>
      <origin
        xyz="0 0 0"
        rpy="0 0 0" />
      <geometry>
        <mesh
          filename="package://4wheel_sus/meshes/LFS.STL" />
      </geometry>
    </collision>
  </link>
  <joint
    name="LFS"
    type="prismatic">
    <origin
      xyz="-0.30216 -0.05081 0.031999"
      rpy="2.834 0 0" />
    <parent
      link="base_link" />
    <child
      link="LFS" />
    <axis
      xyz="0 0.3028 -0.95305" />
    <limit
      lower="0"
      upper="0"
      effort="0"
      velocity="0" />
  </joint>
  <link
    name="LFW">
    <inertial>
      <origin
        xyz="0.0176842754249047 -0.00098214776682639 0.00237717934481885"
        rpy="0 0 0" />
      <mass
        value="0.193585420779862" />
      <inertia
        ixx="0.000253081141332254"
        ixy="-1.35754373945964E-19"
        ixz="-8.02909614531216E-19"
        iyy="0.000136818598566517"
        iyz="-1.01643953670516E-20"
        izz="0.000136818598566517" />
    </inertial>
    <visual>
      <origin
        xyz="0 0 0"
        rpy="0 0 0" />
      <geometry>
        <mesh
          filename="package://4wheel_sus/meshes/LFW.STL" />
      </geometry>
      <material
        name="">
        <color
          rgba="1 1 1 1" />
      </material>
    </visual>
    <collision>
      <origin
        xyz="0 0 0"
        rpy="0 0 0" />
      <geometry>
        <mesh
          filename="package://4wheel_sus/meshes/LFW.STL" />
      </geometry>
    </collision>
  </link>
  <joint
    name="LFW"
    type="continuous">
    <origin
      xyz="0.030411 -0.048258 0.05476"
      rpy="2.4422 0 -3.1416" />
    <parent
      link="LFS" />
    <child
      link="LFW" />
    <axis
      xyz="1 0 0" />
    <limit
      effort="3.1"
      velocity="7" />
  </joint>
  <link
    name="RBS">
    <inertial>
      <origin
        xyz="0.0666875210853819 -0.0256174029954352 0.0272583251967587"
        rpy="0 0 0" />
      <mass
        value="0.26437001106024" />
      <inertia
        ixx="3.20746276473134E-05"
        ixy="-1.44118283521415E-07"
        ixz="-6.30853084344921E-08"
        iyy="6.22704126338856E-05"
        iyz="-2.01894652764204E-07"
        izz="6.28519936954001E-05" />
    </inertial>
    <visual>
      <origin
        xyz="0 0 0"
        rpy="0 0 0" />
      <geometry>
        <mesh
          filename="package://4wheel_sus/meshes/RBS.STL" />
      </geometry>
      <material
        name="">
        <color
          rgba="0.752941176470588 0.752941176470588 0.752941176470588 1" />
      </material>
    </visual>
    <collision>
      <origin
        xyz="0 0 0"
        rpy="0 0 0" />
      <geometry>
        <mesh
          filename="package://4wheel_sus/meshes/RBS.STL" />
      </geometry>
    </collision>
  </link>
  <joint
    name="RBS"
    type="prismatic">
    <origin
      xyz="0.10216 -0.18919 0.034116"
      rpy="2.834 0 -3.1416" />
    <parent
      link="base_link" />
    <child
      link="RBS" />
    <axis
      xyz="0 0.3028 -0.95305" />
    <limit
      lower="0"
      upper="0"
      effort="0"
      velocity="0" />
  </joint>
  <link
    name="RBW">
    <inertial>
      <origin
        xyz="0.0176842754269322 0.00437911242791671 0.00167488661186024"
        rpy="0 0 0" />
      <mass
        value="0.193585420779862" />
      <inertia
        ixx="0.000253081141332253"
        ixy="7.17108670362947E-19"
        ixz="5.47799407276997E-19"
        iyy="0.000136818598566517"
        iyz="-3.3881317890172E-21"
        izz="0.000136818598566517" />
    </inertial>
    <visual>
      <origin
        xyz="0 0 0"
        rpy="0 0 0" />
      <geometry>
        <mesh
          filename="package://4wheel_sus/meshes/RBW.STL" />
      </geometry>
      <material
        name="">
        <color
          rgba="1 1 1 1" />
      </material>
    </visual>
    <collision>
      <origin
        xyz="0 0 0"
        rpy="0 0 0" />
      <geometry>
        <mesh
          filename="package://4wheel_sus/meshes/RBW.STL" />
      </geometry>
    </collision>
  </link>
  <joint
    name="RBW"
    type="continuous">
    <origin
      xyz="0.030411 -0.048899 0.056777"
      rpy="-2.2437 0 -3.1416" />
    <parent
      link="RBS" />
    <child
      link="RBW" />
    <axis
      xyz="1 0 0" />
    <limit
      effort="3.1"
      velocity="7" />
  </joint>
  <link
    name="LBS">
    <inertial>
      <origin
        xyz="0.07244732763785 -0.0024230655827128 -0.0667549990091168"
        rpy="0 0 0" />
      <mass
        value="0.26437001106024" />
      <inertia
        ixx="3.20746276473134E-05"
        ixy="1.44118283521135E-07"
        ixz="6.30853084346611E-08"
        iyy="6.22704126338856E-05"
        iyz="-2.01894652764193E-07"
        izz="6.28519936954001E-05" />
    </inertial>
    <visual>
      <origin
        xyz="0 0 0"
        rpy="0 0 0" />
      <geometry>
        <mesh
          filename="package://4wheel_sus/meshes/LBS.STL" />
      </geometry>
      <material
        name="">
        <color
          rgba="0.752941176470588 0.752941176470588 0.752941176470588 1" />
      </material>
    </visual>
    <collision>
      <origin
        xyz="0 0 0"
        rpy="0 0 0" />
      <geometry>
        <mesh
          filename="package://4wheel_sus/meshes/LBS.STL" />
      </geometry>
    </collision>
  </link>
  <joint
    name="LBS"
    type="prismatic">
    <origin
      xyz="-0.30792 -0.22787 -0.039342"
      rpy="2.834 0 0" />
    <parent
      link="base_link" />
    <child
      link="LBS" />
    <axis
      xyz="0 0.3028 -0.95305" />
    <limit
      lower="0"
      upper="0"
      effort="0"
      velocity="0" />
  </joint>
  <link
    name="LBW">
    <inertial>
      <origin
        xyz="0.0176842754249237 -0.010084618767511 0.0259800171985082"
        rpy="0 0 0" />
      <mass
        value="0.193585420779862" />
      <inertia
        ixx="0.000253081141332254"
        ixy="1.72925527374671E-20"
        ixz="-3.6518488849057E-21"
        iyy="0.000136818598566517"
        iyz="-6.7762635780344E-21"
        izz="0.000136818598566517" />
    </inertial>
    <visual>
      <origin
        xyz="0 0 0"
        rpy="0 0 0" />
      <geometry>
        <mesh
          filename="package://4wheel_sus/meshes/LBW.STL" />
      </geometry>
      <material
        name="">
        <color
          rgba="1 1 1 1" />
      </material>
    </visual>
    <collision>
      <origin
        xyz="0 0 0"
        rpy="0 0 0" />
      <geometry>
        <mesh
          filename="package://4wheel_sus/meshes/LBW.STL" />
      </geometry>
    </collision>
  </link>
  <joint
    name="LBW"
    type="continuous">
    <origin
      xyz="0.036171 -0.0080345 -0.0073174"
      rpy="2.4422 0 3.1416" />
    <parent
      link="LBS" />
    <child
      link="LBW" />
    <axis
      xyz="1 0 0" />
    <limit
      effort="3.1"
      velocity="7" />
  </joint>
  <link
    name="Camera">
    <inertial>
      <origin
        xyz="-0.0238863602658846 -0.0255006342246767 0.0933352701359988"
        rpy="0 0 0" />
      <mass
        value="0.0842240149784746" />
      <inertia
        ixx="1.39666964094511E-05"
        ixy="-8.81675038637699E-10"
        ixz="-1.01039030272292E-09"
        iyy="3.67256475244704E-05"
        iyz="-1.51507840680378E-06"
        izz="3.01150351793437E-05" />
    </inertial>
    <visual>
      <origin
        xyz="0 0 0"
        rpy="0 0 0" />
      <geometry>
        <mesh
          filename="package://4wheel_sus/meshes/Camera.STL" />
      </geometry>
      <material
        name="">
        <color
          rgba="0.752941176470588 0.752941176470588 0.752941176470588 1" />
      </material>
    </visual>
    <collision>
      <origin
        xyz="0 0 0"
        rpy="0 0 0" />
      <geometry>
        <mesh
          filename="package://4wheel_sus/meshes/Camera.STL" />
      </geometry>
    </collision>
  </link>
  <joint
    name="Camera"
    type="fixed">
    <origin
      xyz="-0.13188 -0.10697 0.14474"
      rpy="1.7188 0 3.1056" />
    <parent
      link="base_link" />
    <child
      link="Camera" />
    <axis
      xyz="0 0 0" />
  </joint>
  <link
    name="RPLidar">
    <inertial>
      <origin
        xyz="-0.0784930307037288 0.744427437305917 0.133449661555198"
        rpy="0 0 0" />
      <mass
        value="0.0730845788526277" />
      <inertia
        ixx="1.95808748637193E-05"
        ixy="-4.28390989680129E-07"
        ixz="1.03932705917578E-07"
        iyy="4.14184477875127E-05"
        iyz="-9.42731071230568E-09"
        izz="2.41250058024956E-05" />
    </inertial>
    <visual>
      <origin
        xyz="0 0 0"
        rpy="0 0 0" />
      <geometry>
        <mesh
          filename="package://4wheel_sus/meshes/RPLidar.STL" />
      </geometry>
      <material
        name="">
        <color
          rgba="0.792156862745098 0.819607843137255 0.933333333333333 1" />
      </material>
    </visual>
    <collision>
      <origin
        xyz="0 0 0"
        rpy="0 0 0" />
      <geometry>
        <mesh
          filename="package://4wheel_sus/meshes/RPLidar.STL" />
      </geometry>
    </collision>
  </link>
  <joint
    name="RPLidar"
    type="fixed">
    <origin
      xyz="-0.237163065688857 0.0165890879455942 -0.568694502755534"
      rpy="1.57079632679489 0 1.59731568067692" />
    <parent
      link="base_link" />
    <child
      link="RPLidar" />
    <axis
      xyz="0 0 0" />
  </joint>
</robot>